[2025-04-01T00:29:22.919-0300] {local_task_job_runner.py:120} INFO - ::group::Pre task execution logs
[2025-04-01T00:29:22.923-0300] {taskinstance.py:2073} INFO - Dependencies all met for dep_context=non-requeueable deps ti=<TaskInstance: monthly_employee_changes_report.send_failure_email scheduled__2025-03-01T03:00:00+00:00 [queued]>
[2025-04-01T00:29:22.925-0300] {taskinstance.py:2073} INFO - Dependencies all met for dep_context=requeueable deps ti=<TaskInstance: monthly_employee_changes_report.send_failure_email scheduled__2025-03-01T03:00:00+00:00 [queued]>
[2025-04-01T00:29:22.925-0300] {taskinstance.py:2303} INFO - Starting attempt 1 of 3
[2025-04-01T00:29:22.930-0300] {taskinstance.py:2327} INFO - Executing <Task(EmailOperator): send_failure_email> on 2025-03-01 03:00:00+00:00
[2025-04-01T00:29:22.932-0300] {standard_task_runner.py:63} INFO - Started process 13987 to run task
[2025-04-01T00:29:22.935-0300] {standard_task_runner.py:90} INFO - Running: ['airflow', 'tasks', 'run', 'monthly_employee_changes_report', 'send_failure_email', 'scheduled__2025-03-01T03:00:00+00:00', '--job-id', '27', '--raw', '--subdir', 'DAGS_FOLDER/monthly_employee_changes_report_dag.py', '--cfg-path', '/var/folders/pw/ybzcyby54d787c124gv_5tjw0000gn/T/tmptboq157b']
[2025-04-01T00:29:22.936-0300] {standard_task_runner.py:91} INFO - Job 27: Subtask send_failure_email
[2025-04-01T00:29:22.950-0300] {task_command.py:426} INFO - Running <TaskInstance: monthly_employee_changes_report.send_failure_email scheduled__2025-03-01T03:00:00+00:00 [running]> on host ordenador-portatil-de-user-2.local
[2025-04-01T00:29:22.972-0300] {taskinstance.py:2644} INFO - Exporting env vars: AIRFLOW_CTX_DAG_EMAIL='admin@example.com' AIRFLOW_CTX_DAG_OWNER='airflow' AIRFLOW_CTX_DAG_ID='monthly_employee_changes_report' AIRFLOW_CTX_TASK_ID='send_failure_email' AIRFLOW_CTX_EXECUTION_DATE='2025-03-01T03:00:00+00:00' AIRFLOW_CTX_TRY_NUMBER='1' AIRFLOW_CTX_DAG_RUN_ID='scheduled__2025-03-01T03:00:00+00:00'
[2025-04-01T00:29:22.972-0300] {taskinstance.py:430} INFO - ::endgroup::
[2025-04-01T00:29:22.982-0300] {logging_mixin.py:188} WARNING - /Users/user/Documents/repo test eng/env/lib/python3.10/site-packages/airflow/utils/email.py:154 RemovedInAirflow3Warning: Fetching SMTP credentials from configuration variables will be deprecated in a future release. Please set credentials using a connection instead.
[2025-04-01T00:29:22.982-0300] {configuration.py:1050} WARNING - section/key [smtp/smtp_user] not found in config
[2025-04-01T00:29:22.982-0300] {email.py:271} INFO - Email alerting: attempt 1
[2025-04-01T00:29:22.983-0300] {taskinstance.py:441} INFO - ::group::Post task execution logs
[2025-04-01T00:29:22.983-0300] {taskinstance.py:2890} ERROR - Task failed with exception
Traceback (most recent call last):
  File "/Users/user/Documents/repo test eng/env/lib/python3.10/site-packages/airflow/models/taskinstance.py", line 465, in _execute_task
    result = _execute_callable(context=context, **execute_callable_kwargs)
  File "/Users/user/Documents/repo test eng/env/lib/python3.10/site-packages/airflow/models/taskinstance.py", line 432, in _execute_callable
    return execute_callable(context=context, **execute_callable_kwargs)
  File "/Users/user/Documents/repo test eng/env/lib/python3.10/site-packages/airflow/models/baseoperator.py", line 400, in wrapper
    return func(self, *args, **kwargs)
  File "/Users/user/Documents/repo test eng/env/lib/python3.10/site-packages/airflow/operators/email.py", line 79, in execute
    send_email(
  File "/Users/user/Documents/repo test eng/env/lib/python3.10/site-packages/airflow/utils/email.py", line 80, in send_email
    return backend(
  File "/Users/user/Documents/repo test eng/env/lib/python3.10/site-packages/airflow/utils/email.py", line 154, in send_email_smtp
    send_mime_email(e_from=mail_from, e_to=recipients, mime_msg=msg, conn_id=conn_id, dryrun=dryrun)
  File "/Users/user/Documents/repo test eng/env/lib/python3.10/site-packages/airflow/utils/email.py", line 273, in send_mime_email
    smtp_conn = _get_smtp_connection(smtp_host, smtp_port, smtp_timeout, smtp_ssl)
  File "/Users/user/Documents/repo test eng/env/lib/python3.10/site-packages/airflow/utils/email.py", line 317, in _get_smtp_connection
    return smtplib.SMTP(host=host, port=port, timeout=timeout)
  File "/opt/homebrew/Caskroom/miniforge/base/lib/python3.10/smtplib.py", line 255, in __init__
    (code, msg) = self.connect(host, port)
  File "/opt/homebrew/Caskroom/miniforge/base/lib/python3.10/smtplib.py", line 341, in connect
    self.sock = self._get_socket(host, port, self.timeout)
  File "/opt/homebrew/Caskroom/miniforge/base/lib/python3.10/smtplib.py", line 312, in _get_socket
    return socket.create_connection((host, port), timeout,
  File "/opt/homebrew/Caskroom/miniforge/base/lib/python3.10/socket.py", line 845, in create_connection
    raise err
  File "/opt/homebrew/Caskroom/miniforge/base/lib/python3.10/socket.py", line 833, in create_connection
    sock.connect(sa)
ConnectionRefusedError: [Errno 61] Connection refused
[2025-04-01T00:29:22.985-0300] {taskinstance.py:1205} INFO - Marking task as UP_FOR_RETRY. dag_id=monthly_employee_changes_report, task_id=send_failure_email, execution_date=20250301T030000, start_date=20250401T032922, end_date=20250401T032922
[2025-04-01T00:29:22.989-0300] {logging_mixin.py:188} WARNING - /Users/user/Documents/repo test eng/env/lib/python3.10/site-packages/airflow/utils/email.py:154 RemovedInAirflow3Warning: Fetching SMTP credentials from configuration variables will be deprecated in a future release. Please set credentials using a connection instead.
[2025-04-01T00:29:22.990-0300] {configuration.py:1050} WARNING - section/key [smtp/smtp_user] not found in config
[2025-04-01T00:29:22.990-0300] {email.py:271} INFO - Email alerting: attempt 1
[2025-04-01T00:29:22.991-0300] {configuration.py:1050} WARNING - section/key [smtp/smtp_user] not found in config
[2025-04-01T00:29:22.992-0300] {email.py:271} INFO - Email alerting: attempt 1
[2025-04-01T00:29:22.992-0300] {taskinstance.py:879} ERROR - Failed to send email to: admin@example.com
Traceback (most recent call last):
  File "/Users/user/Documents/repo test eng/env/lib/python3.10/site-packages/airflow/models/taskinstance.py", line 2476, in _run_raw_task
    self._execute_task_with_callbacks(context, test_mode, session=session)
  File "/Users/user/Documents/repo test eng/env/lib/python3.10/site-packages/airflow/models/taskinstance.py", line 2663, in _execute_task_with_callbacks
    result = self._execute_task(context, task_orig)
  File "/Users/user/Documents/repo test eng/env/lib/python3.10/site-packages/airflow/models/taskinstance.py", line 2686, in _execute_task
    return _execute_task(self, context, task_orig)
  File "/Users/user/Documents/repo test eng/env/lib/python3.10/site-packages/airflow/models/taskinstance.py", line 465, in _execute_task
    result = _execute_callable(context=context, **execute_callable_kwargs)
  File "/Users/user/Documents/repo test eng/env/lib/python3.10/site-packages/airflow/models/taskinstance.py", line 432, in _execute_callable
    return execute_callable(context=context, **execute_callable_kwargs)
  File "/Users/user/Documents/repo test eng/env/lib/python3.10/site-packages/airflow/models/baseoperator.py", line 400, in wrapper
    return func(self, *args, **kwargs)
  File "/Users/user/Documents/repo test eng/env/lib/python3.10/site-packages/airflow/operators/email.py", line 79, in execute
    send_email(
  File "/Users/user/Documents/repo test eng/env/lib/python3.10/site-packages/airflow/utils/email.py", line 80, in send_email
    return backend(
  File "/Users/user/Documents/repo test eng/env/lib/python3.10/site-packages/airflow/utils/email.py", line 154, in send_email_smtp
    send_mime_email(e_from=mail_from, e_to=recipients, mime_msg=msg, conn_id=conn_id, dryrun=dryrun)
  File "/Users/user/Documents/repo test eng/env/lib/python3.10/site-packages/airflow/utils/email.py", line 273, in send_mime_email
    smtp_conn = _get_smtp_connection(smtp_host, smtp_port, smtp_timeout, smtp_ssl)
  File "/Users/user/Documents/repo test eng/env/lib/python3.10/site-packages/airflow/utils/email.py", line 317, in _get_smtp_connection
    return smtplib.SMTP(host=host, port=port, timeout=timeout)
  File "/opt/homebrew/Caskroom/miniforge/base/lib/python3.10/smtplib.py", line 255, in __init__
    (code, msg) = self.connect(host, port)
  File "/opt/homebrew/Caskroom/miniforge/base/lib/python3.10/smtplib.py", line 341, in connect
    self.sock = self._get_socket(host, port, self.timeout)
  File "/opt/homebrew/Caskroom/miniforge/base/lib/python3.10/smtplib.py", line 312, in _get_socket
    return socket.create_connection((host, port), timeout,
  File "/opt/homebrew/Caskroom/miniforge/base/lib/python3.10/socket.py", line 845, in create_connection
    raise err
  File "/opt/homebrew/Caskroom/miniforge/base/lib/python3.10/socket.py", line 833, in create_connection
    sock.connect(sa)
ConnectionRefusedError: [Errno 61] Connection refused

During handling of the above exception, another exception occurred:

Traceback (most recent call last):
  File "/Users/user/Documents/repo test eng/env/lib/python3.10/site-packages/airflow/models/taskinstance.py", line 1063, in _email_alert
    send_email(task.email, subject, html_content)
  File "/Users/user/Documents/repo test eng/env/lib/python3.10/site-packages/airflow/utils/email.py", line 80, in send_email
    return backend(
  File "/Users/user/Documents/repo test eng/env/lib/python3.10/site-packages/airflow/utils/email.py", line 154, in send_email_smtp
    send_mime_email(e_from=mail_from, e_to=recipients, mime_msg=msg, conn_id=conn_id, dryrun=dryrun)
  File "/Users/user/Documents/repo test eng/env/lib/python3.10/site-packages/airflow/utils/email.py", line 273, in send_mime_email
    smtp_conn = _get_smtp_connection(smtp_host, smtp_port, smtp_timeout, smtp_ssl)
  File "/Users/user/Documents/repo test eng/env/lib/python3.10/site-packages/airflow/utils/email.py", line 317, in _get_smtp_connection
    return smtplib.SMTP(host=host, port=port, timeout=timeout)
  File "/opt/homebrew/Caskroom/miniforge/base/lib/python3.10/smtplib.py", line 255, in __init__
    (code, msg) = self.connect(host, port)
  File "/opt/homebrew/Caskroom/miniforge/base/lib/python3.10/smtplib.py", line 341, in connect
    self.sock = self._get_socket(host, port, self.timeout)
  File "/opt/homebrew/Caskroom/miniforge/base/lib/python3.10/smtplib.py", line 312, in _get_socket
    return socket.create_connection((host, port), timeout,
  File "/opt/homebrew/Caskroom/miniforge/base/lib/python3.10/socket.py", line 845, in create_connection
    raise err
  File "/opt/homebrew/Caskroom/miniforge/base/lib/python3.10/socket.py", line 833, in create_connection
    sock.connect(sa)
ConnectionRefusedError: [Errno 61] Connection refused

During handling of the above exception, another exception occurred:

Traceback (most recent call last):
  File "/Users/user/Documents/repo test eng/env/lib/python3.10/site-packages/airflow/models/taskinstance.py", line 877, in _handle_failure
    task_instance.email_alert(error, failure_context["task"])
  File "/Users/user/Documents/repo test eng/env/lib/python3.10/site-packages/airflow/models/taskinstance.py", line 3148, in email_alert
    _email_alert(task_instance=self, exception=exception, task=task)
  File "/Users/user/Documents/repo test eng/env/lib/python3.10/site-packages/airflow/models/taskinstance.py", line 1065, in _email_alert
    send_email(task.email, subject, html_content_err)
  File "/Users/user/Documents/repo test eng/env/lib/python3.10/site-packages/airflow/utils/email.py", line 80, in send_email
    return backend(
  File "/Users/user/Documents/repo test eng/env/lib/python3.10/site-packages/airflow/utils/email.py", line 154, in send_email_smtp
    send_mime_email(e_from=mail_from, e_to=recipients, mime_msg=msg, conn_id=conn_id, dryrun=dryrun)
  File "/Users/user/Documents/repo test eng/env/lib/python3.10/site-packages/airflow/utils/email.py", line 273, in send_mime_email
    smtp_conn = _get_smtp_connection(smtp_host, smtp_port, smtp_timeout, smtp_ssl)
  File "/Users/user/Documents/repo test eng/env/lib/python3.10/site-packages/airflow/utils/email.py", line 317, in _get_smtp_connection
    return smtplib.SMTP(host=host, port=port, timeout=timeout)
  File "/opt/homebrew/Caskroom/miniforge/base/lib/python3.10/smtplib.py", line 255, in __init__
    (code, msg) = self.connect(host, port)
  File "/opt/homebrew/Caskroom/miniforge/base/lib/python3.10/smtplib.py", line 341, in connect
    self.sock = self._get_socket(host, port, self.timeout)
  File "/opt/homebrew/Caskroom/miniforge/base/lib/python3.10/smtplib.py", line 312, in _get_socket
    return socket.create_connection((host, port), timeout,
  File "/opt/homebrew/Caskroom/miniforge/base/lib/python3.10/socket.py", line 845, in create_connection
    raise err
  File "/opt/homebrew/Caskroom/miniforge/base/lib/python3.10/socket.py", line 833, in create_connection
    sock.connect(sa)
ConnectionRefusedError: [Errno 61] Connection refused
[2025-04-01T00:29:22.995-0300] {standard_task_runner.py:110} ERROR - Failed to execute job 27 for task send_failure_email ([Errno 61] Connection refused; 13987)
[2025-04-01T00:29:22.997-0300] {local_task_job_runner.py:240} INFO - Task exited with return code 1
[2025-04-01T00:29:23.002-0300] {taskinstance.py:3482} INFO - 0 downstream tasks scheduled from follow-on schedule check
[2025-04-01T00:29:23.002-0300] {local_task_job_runner.py:222} INFO - ::endgroup::
