[2025-03-31T21:07:12.362-0300] {scheduler_job_runner.py:769} ERROR - Executor reports task instance <TaskInstance: test_new_dag.load_and_clean_data manual__2025-03-31T23:46:10+00:00 [queued]> finished (failed) although the task says it's queued. (Info: None) Was the task killed externally?
