[2025-03-31T20:50:57.730-0300] {local_task_job_runner.py:120} INFO - ::group::Pre task execution logs
[2025-03-31T20:50:57.735-0300] {taskinstance.py:2073} INFO - Dependencies all met for dep_context=non-requeueable deps ti=<TaskInstance: test_new_dag.load_and_clean_data manual__2025-03-31T23:46:10+00:00 [queued]>
[2025-03-31T20:50:57.737-0300] {taskinstance.py:2073} INFO - Dependencies all met for dep_context=requeueable deps ti=<TaskInstance: test_new_dag.load_and_clean_data manual__2025-03-31T23:46:10+00:00 [queued]>
[2025-03-31T20:50:57.737-0300] {taskinstance.py:2303} INFO - Starting attempt 4 of 6
[2025-03-31T20:50:57.741-0300] {taskinstance.py:2327} INFO - Executing <Task(PythonOperator): load_and_clean_data> on 2025-03-31 23:46:10+00:00
[2025-03-31T20:50:57.743-0300] {standard_task_runner.py:63} INFO - Started process 10388 to run task
[2025-03-31T20:50:57.746-0300] {standard_task_runner.py:90} INFO - Running: ['airflow', 'tasks', 'run', 'test_new_dag', 'load_and_clean_data', 'manual__2025-03-31T23:46:10+00:00', '--job-id', '7', '--raw', '--subdir', 'DAGS_FOLDER/test_new_dag.py', '--cfg-path', '/var/folders/pw/ybzcyby54d787c124gv_5tjw0000gn/T/tmpe57tqxum']
[2025-03-31T20:50:57.747-0300] {standard_task_runner.py:91} INFO - Job 7: Subtask load_and_clean_data
[2025-03-31T20:50:57.766-0300] {task_command.py:426} INFO - Running <TaskInstance: test_new_dag.load_and_clean_data manual__2025-03-31T23:46:10+00:00 [running]> on host ordenador-portatil-de-user-2.local
[2025-03-31T20:50:57.787-0300] {taskinstance.py:2644} INFO - Exporting env vars: AIRFLOW_CTX_DAG_OWNER='airflow' AIRFLOW_CTX_DAG_ID='test_new_dag' AIRFLOW_CTX_TASK_ID='load_and_clean_data' AIRFLOW_CTX_EXECUTION_DATE='2025-03-31T23:46:10+00:00' AIRFLOW_CTX_TRY_NUMBER='4' AIRFLOW_CTX_DAG_RUN_ID='manual__2025-03-31T23:46:10+00:00'
[2025-03-31T20:50:57.787-0300] {taskinstance.py:430} INFO - ::endgroup::
[2025-03-31T21:06:07.288-0300] {local_task_job_runner.py:310} WARNING - State of this instance has been externally set to restarting. Terminating instance.
[2025-03-31T21:06:07.288-0300] {local_task_job_runner.py:222} INFO - ::endgroup::
[2025-03-31T21:06:07.293-0300] {process_utils.py:132} INFO - Sending Signals.SIGTERM to group 10388. PIDs of all processes in the group: [10389, 10388]
[2025-03-31T21:06:07.293-0300] {process_utils.py:87} INFO - Sending the signal Signals.SIGTERM to group 10388
[2025-03-31T21:07:07.325-0300] {process_utils.py:150} WARNING - process psutil.Process(pid=10389, name='java', status='zombie', started='20:50:57') did not respond to SIGTERM. Trying SIGKILL
[2025-03-31T21:07:07.326-0300] {process_utils.py:150} WARNING - process psutil.Process(pid=10388, name='python3.10', status='running', started='20:50:57') did not respond to SIGTERM. Trying SIGKILL
[2025-03-31T21:07:07.326-0300] {process_utils.py:87} INFO - Sending the signal Signals.SIGKILL to group 10388
[2025-03-31T21:07:07.334-0300] {process_utils.py:80} INFO - Process psutil.Process(pid=10389, name='java', status='terminated', started='20:50:57') (10389) terminated with exit code None
[2025-03-31T21:07:07.334-0300] {process_utils.py:80} INFO - Process psutil.Process(pid=10388, name='python3.10', status='terminated', exitcode=<Negsignal.SIGKILL: -9>, started='20:50:57') (10388) terminated with exit code Negsignal.SIGKILL
[2025-03-31T21:07:07.335-0300] {standard_task_runner.py:178} ERROR - Job 7 was killed before it finished (likely due to running out of memory)
