[2025-03-31T20:46:47.798-0300] {local_task_job_runner.py:120} INFO - ::group::Pre task execution logs
[2025-03-31T20:46:47.802-0300] {taskinstance.py:2073} INFO - Dependencies all met for dep_context=non-requeueable deps ti=<TaskInstance: test_new_dag.load_and_clean_data manual__2025-03-31T23:46:10+00:00 [queued]>
[2025-03-31T20:46:47.804-0300] {taskinstance.py:2073} INFO - Dependencies all met for dep_context=requeueable deps ti=<TaskInstance: test_new_dag.load_and_clean_data manual__2025-03-31T23:46:10+00:00 [queued]>
[2025-03-31T20:46:47.804-0300] {taskinstance.py:2303} INFO - Starting attempt 2 of 4
[2025-03-31T20:46:47.808-0300] {taskinstance.py:2327} INFO - Executing <Task(PythonOperator): load_and_clean_data> on 2025-03-31 23:46:10+00:00
[2025-03-31T20:46:47.810-0300] {standard_task_runner.py:63} INFO - Started process 10273 to run task
[2025-03-31T20:46:47.813-0300] {standard_task_runner.py:90} INFO - Running: ['airflow', 'tasks', 'run', 'test_new_dag', 'load_and_clean_data', 'manual__2025-03-31T23:46:10+00:00', '--job-id', '4', '--raw', '--subdir', 'DAGS_FOLDER/test_new_dag.py', '--cfg-path', '/var/folders/pw/ybzcyby54d787c124gv_5tjw0000gn/T/tmpg3ialz78']
[2025-03-31T20:46:47.814-0300] {standard_task_runner.py:91} INFO - Job 4: Subtask load_and_clean_data
[2025-03-31T20:46:47.832-0300] {task_command.py:426} INFO - Running <TaskInstance: test_new_dag.load_and_clean_data manual__2025-03-31T23:46:10+00:00 [running]> on host ordenador-portatil-de-user-2.local
[2025-03-31T20:46:47.856-0300] {taskinstance.py:2644} INFO - Exporting env vars: AIRFLOW_CTX_DAG_OWNER='airflow' AIRFLOW_CTX_DAG_ID='test_new_dag' AIRFLOW_CTX_TASK_ID='load_and_clean_data' AIRFLOW_CTX_EXECUTION_DATE='2025-03-31T23:46:10+00:00' AIRFLOW_CTX_TRY_NUMBER='2' AIRFLOW_CTX_DAG_RUN_ID='manual__2025-03-31T23:46:10+00:00'
[2025-03-31T20:46:47.856-0300] {taskinstance.py:430} INFO - ::endgroup::
[2025-03-31T20:46:47.863-0300] {taskinstance.py:441} INFO - ::group::Post task execution logs
[2025-03-31T20:46:47.863-0300] {taskinstance.py:2890} ERROR - Task failed with exception
Traceback (most recent call last):
  File "/Users/user/Documents/repo test eng/env/lib/python3.10/site-packages/airflow/models/taskinstance.py", line 465, in _execute_task
    result = _execute_callable(context=context, **execute_callable_kwargs)
  File "/Users/user/Documents/repo test eng/env/lib/python3.10/site-packages/airflow/models/taskinstance.py", line 432, in _execute_callable
    return execute_callable(context=context, **execute_callable_kwargs)
  File "/Users/user/Documents/repo test eng/env/lib/python3.10/site-packages/airflow/models/baseoperator.py", line 400, in wrapper
    return func(self, *args, **kwargs)
  File "/Users/user/Documents/repo test eng/env/lib/python3.10/site-packages/airflow/operators/python.py", line 235, in execute
    return_value = self.execute_callable()
  File "/Users/user/Documents/repo test eng/env/lib/python3.10/site-packages/airflow/operators/python.py", line 252, in execute_callable
    return self.python_callable(*self.op_args, **self.op_kwargs)
  File "/Users/user/Documents/repo test eng/airflow_data/dags/test_new_dag.py", line 26, in load_and_clean
    from etl.data_loader import create_spark_session, load_all_tables
ModuleNotFoundError: No module named 'etl'
[2025-03-31T20:46:47.865-0300] {taskinstance.py:1205} INFO - Marking task as UP_FOR_RETRY. dag_id=test_new_dag, task_id=load_and_clean_data, execution_date=20250331T234610, start_date=20250331T234647, end_date=20250331T234647
[2025-03-31T20:46:47.868-0300] {standard_task_runner.py:110} ERROR - Failed to execute job 4 for task load_and_clean_data (No module named 'etl'; 10273)
[2025-03-31T20:46:47.872-0300] {local_task_job_runner.py:240} INFO - Task exited with return code 1
[2025-03-31T20:46:47.879-0300] {taskinstance.py:3482} INFO - 0 downstream tasks scheduled from follow-on schedule check
[2025-03-31T20:46:47.879-0300] {local_task_job_runner.py:222} INFO - ::endgroup::
