[2025-03-31T21:07:12.388-0300] {scheduler_job_runner.py:769} ERROR - Executor reports task instance <TaskInstance: test_new_dag.load_and_clean_data scheduled__2025-03-01T00:00:00+00:00 [queued]> finished (failed) although the task says it's queued. (Info: None) Was the task killed externally?
